Workbook

Sheet Raw-Data
A1: ticket_id | B1: created_at | C1: customer_id | D1: channel | E1: priority | F1: category | G1: first_response_min | H1: resolution_min | I1: status | J1: satisfaction
A2: TCK-000001 | B2: 2025-07-01T00:00:00Z | C2: 1175 | D2: Chat | E2: Urgent | F2: Data import | G2: 3 | H2: 412 | I2: closed
A3: TCK-000002 | B3: 2025-07-01T08:45:36Z | C3: 1019 | D3: Social | E3: High | F3: Data import | G3: 34 | H3: 507 | I3: resolved
A4: TCK-000003 | B4: 2025-07-01T17:31:12Z | C4: 1278 | D4: Chat | E4: Urgent | F4: Performance | G4: 8 | H4: 305 | I4: closed
A5: TCK-000004 | B5: 2025-07-02T02:16:48Z | C5: 1448 | D5: Web form | E5: Normal | F5: Billing | G5: 65 | I5: open
A6: TCK-000005 | B6: 2025-07-02T11:02:24Z | C6: 1936 | D6: Email | E6: Low | F6: Feature request | G6: 431 | H6: 3785 | I6: closed | J6: 4
A7: TCK-000006 | B7: 2025-07-02T19:48:00Z | C7: 1471 | D7: Social | E7: Low | F7: Feature request | G7: 302 | H7: 1808 | I7: closed | J7: 1
A8: TCK-000007 | B8: 2025-07-03T04:33:36Z | C8: 1949 | D8: Web form | E8: Low | F8: Performance | G8: 206 | H8: 2717 | I8: closed | J8: 1
A9: TCK-000008 | B9: 2025-07-03T13:19:12Z | C9: 1968 | D9: Chat | E9: Normal | F9: Billing | G9: 85 | H9: 771 | I9: closed
A10: TCK-000009 | B10: 2025-07-03T22:04:48Z | C10: 1750 | D10: Chat | E10: Normal | F10: Integration | G10: 32 | I10: pending
A11: TCK-000010 | B11: 2025-07-04T06:50:24Z | C11: 1591 | D11: Phone | E11: Normal | F11: Integration | G11: 63 | H11: 1975 | I11: closed | J11: 2
A12: TCK-000011 | B12: 2025-07-04T15:36:00Z | C12: 1908 | D12: Chat | E12: High | F12: Data import | G12: 21 | H12: 174 | I12: resolved | J12: 1
A13: TCK-000012 | B13: 2025-07-05T00:21:36Z | C13: 1982 | D13: Social | E13: Low | F13: Performance | G13: 343 | H13: 6881 | I13: closed
A14: TCK-000013 | B14: 2025-07-05T09:07:12Z | C14: 1099 | D14: Web form | E14: Low | F14: Bug report | G14: 442 | H14: 6637 | I14: closed | J14: 1
A15: TCK-000014 | B15: 2025-07-05T17:52:48Z | C15: 1055 | D15: Web form | E15: Urgent | F15: Feature request | G15: 10 | H15: 406 | I15: closed
A16: TCK-000015 | B16: 2025-07-06T02:38:24Z | C16: 1214 | D16: Phone | E16: Low | F16: Export | G16: 122 | H16: 2695 | I16: resolved | J16: 3
A17: TCK-000016 | B17: 2025-07-06T11:24:00Z | C17: 1730 | D17: Web form | E17: Urgent | F17: Integration | G17: 3 | H17: 173 | I17: closed | J17: 2
A18: TCK-000017 | B18: 2025-07-06T20:09:36Z | C18: 1469 | D18: Phone | E18: Low | F18: Account | G18: 337 | H18: 6240 | I18: closed
A19: TCK-000018 | B19: 2025-07-07T04:55:12Z | C19: 1802 | D19: Email | E19: Normal | F19: Export | G19: 157 | I19: pending
A20: TCK-000019 | B20: 2025-07-07T13:40:48Z | C20: 1538 | D20: Social | E20: Normal | F20: Account | G20: 166 | H20: 1810 | I20: resolved
A21: TCK-000020 | B21: 2025-07-07T22:26:24Z | C21: 1295 | D21: Web form | E21: Urgent | F21: Login | G21: 3 | H21: 123 | I21: resolved | J21: 4
A22: TCK-000021 | B22: 2025-07-08T07:12:00Z | C22: 1646 | D22: Web form | E22: High | F22: Data import | G22: 15 | I22: open
A23: TCK-000022 | B23: 2025-07-08T15:57:36Z | C23: 1880 | D23: Social | E23: Normal | F23: Login | G23: 46 | I23: open
A24: TCK-000023 | B24: 2025-07-09T00:43:12Z | C24: 1808 | D24: Web form | E24: Low | F24: Performance | G24: 217 | H24: 6190 | I24: closed
A25: TCK-000024 | B25: 2025-07-09T09:28:48Z | C25: 1887 | D25: Social | E25: Low | F25: Integration | G25: 263 | H25: 7047 | I25: closed
A26: TCK-000025 | B26: 2025-07-09T18:14:24Z | C26: 1909 | D26: Phone | E26: Low | F26: Performance | G26: 446 | I26: open
A27: TCK-000026 | B27: 2025-07-10T03:00:00Z | C27: 1950 | D27: Chat | E27: Low | F27: Account | G27: 165 | I27: open
A28: TCK-000027 | B28: 2025-07-10T11:45:36Z | C28: 1028 | D28: Phone | E28: Normal | F28: Export | G28: 123 | H28: 792 | I28: resolved | J28: 2
A29: TCK-000028 | B29: 2025-07-10T20:31:12Z | C29: 1035 | D29: Web form | E29: High | F29: Feature request | G29: 24 | H29: 235 | I29: closed | J29: 4
A30: TCK-000029 | B30: 2025-07-11T05:16:48Z | C30: 1426 | D30: Chat | E30: Low | F30: Feature request | G30: 405 | H30: 4942 | I30: closed | J30: 3
A31: TCK-000030 | B31: 2025-07-11T14:02:24Z | C31: 1908 | D31: Phone | E31: Low | F31: Account | G31: 432 | H31: 2314 | I31: closed | J31: 3
A32: TCK-000031 | B32: 2025-07-11T22:48:00Z | C32: 1540 | D32: Web form | E32: Normal | F32: Billing | G32: 90 | I32: open
A33: TCK-000032 | B33: 2025-07-12T07:33:36Z | C33: 1059 | D33: Web form | E33: Urgent | F33: Bug report | G33: 2 | H33: 221 | I33: closed | J33: 4
A34: TCK-000033 | B34: 2025-07-12T16:19:12Z | C34: 1205 | D34: Email | E34: Urgent | F34: Data import | G34: 9 | H34: 422 | I34: resolved | J34: 3
A35: TCK-000034 | B35: 2025-07-13T01:04:48Z | C35: 1441 | D35: Email | E35: Normal | F35: Billing | G35: 150 | H35: 1715 | I35: closed | J35: 1
A36: TCK-000035 | B36: 2025-07-13T09:50:24Z | C36: 1403 | D36: Chat | E36: Normal | F36: Export | G36: 36 | H36: 3180 | I36: resolved
A37: TCK-000036 | B37: 2025-07-13T18:36:00Z | C37: 1702 | D37: Web form | E37: Low | F37: Integration | G37: 233 | H37: 2898 | I37: resolved
A38: TCK-000037 | B38: 2025-07-14T03:21:36Z | C38: 1041 | D38: Phone | E38: Urgent | F38: Integration | G38: 7 | H38: 427 | I38: closed | J38: 4
A39: TCK-000038 | B39: 2025-07-14T12:07:12Z | C39: 1169 | D39: Web form | E39: Low | F39: Bug report | G39: 335 | H39: 5407 | I39: closed
A40: TCK-000039 | B40: 2025-07-14T20:52:48Z | C40: 1116 | D40: Web form | E40: Normal | F40: Integration | G40: 103 | I40: open
...

Sheet Clean-Data
A1: ticket_id | B1: created_at | C1: customer_id | D1: channel | E1: priority | F1: category | G1: first_response_min | H1: resolution_min | I1: status | J1: satisfaction | K1: created_date | L1: resolution_hours | M1: response_hours | N1: SLA_Status | O1: Satisfaction_Category | P1: Resolution_Status | Q1: Month | R1: Month_Date
A2: TCK-000001 | B2: 2025-07-01T00:00:00Z | C2: 1175 | D2: Chat | E2: Urgent | F2: Data import | G2: 3 | H2: 412 | I2: closed | K2: =IF(B2="","",DATEVALUE(LEFT(B2,10))) -> 45839 | L2: =IF(H2="","",H2/60) -> 6.8666667 | M2: =IF(G2="","",G2/60) -> 0.05 | N2: =IF(L2="","Open",IF(L2<=IF(E2="Urgent",8,IF(E2="High",24,IF(E2="Normal",48,72))),"Within SLA","Breached")) -> Within SLA | O2: =IF(J2="","No Rating",IF(J2>=4,"Satisfied",IF(J2=3,"Neutral","Dissatisfied"))) -> No Rating | P2: =IF(I2="Closed","Resolved",IF(I2="Resolved","Resolved","Unresolved")) -> Resolved | Q2: =IF(K2="","",TEXT(K2,"mmm-yyyy")) -> Jul-2025 | R2: =IF(K2="","",DATE(YEAR(K2),MONTH(K2),1)) -> 45839
A3: TCK-000002 | B3: 2025-07-01T08:45:36Z | C3: 1019 | D3: Social | E3: High | F3: Data import | G3: 34 | H3: 507 | I3: resolved | K3: =IF(B3="","",DATEVALUE(LEFT(B3,10))) -> 45839 | L3: =IF(H3="","",H3/60) -> 8.45 | M3: =IF(G3="","",G3/60) -> 0.56666667 | N3: =IF(L3="","Open",IF(L3<=IF(E3="Urgent",8,IF(E3="High",24,IF(E3="Normal",48,72))),"Within SLA","Breached")) -> Within SLA | O3: =IF(J3="","No Rating",IF(J3>=4,"Satisfied",IF(J3=3,"Neutral","Dissatisfied"))) -> No Rating | P3: =IF(I3="Closed","Resolved",IF(I3="Resolved","Resolved","Unresolved")) -> Resolved | Q3: =IF(K3="","",TEXT(K3,"mmm-yyyy")) -> Jul-2025 | R3: =IF(K3="","",DATE(YEAR(K3),MONTH(K3),1)) -> 45839
A4: TCK-000003 | B4: 2025-07-01T17:31:12Z | C4: 1278 | D4: Chat | E4: Urgent | F4: Performance | G4: 8 | H4: 305 | I4: closed | K4: =IF(B4="","",DATEVALUE(LEFT(B4,10))) -> 45839 | L4: =IF(H4="","",H4/60) -> 5.0833333 | M4: =IF(G4="","",G4/60) -> 0.13333333 | N4: =IF(L4="","Open",IF(L4<=IF(E4="Urgent",8,IF(E4="High",24,IF(E4="Normal",48,72))),"Within SLA","Breached")) -> Within SLA | O4: =IF(J4="","No Rating",IF(J4>=4,"Satisfied",IF(J4=3,"Neutral","Dissatisfied"))) -> No Rating | P4: =IF(I4="Closed","Resolved",IF(I4="Resolved","Resolved","Unresolved")) -> Resolved | Q4: =IF(K4="","",TEXT(K4,"mmm-yyyy")) -> Jul-2025 | R4: =IF(K4="","",DATE(YEAR(K4),MONTH(K4),1)) -> 45839
A5: TCK-000004 | B5: 2025-07-02T02:16:48Z | C5: 1448 | D5: Web form | E5: Normal | F5: Billing | G5: 65 | I5: open | K5: =IF(B5="","",DATEVALUE(LEFT(B5,10))) -> 45840 | L5: =IF(H5="","",H5/60) | M5: =IF(G5="","",G5/60) -> 1.0833333 | N5: =IF(L5="","Open",IF(L5<=IF(E5="Urgent",8,IF(E5="High",24,IF(E5="Normal",48,72))),"Within SLA","Breached")) -> Open | O5: =IF(J5="","No Rating",IF(J5>=4,"Satisfied",IF(J5=3,"Neutral","Dissatisfied"))) -> No Rating | P5: =IF(I5="Closed","Resolved",IF(I5="Resolved","Resolved","Unresolved")) -> Unresolved | Q5: =IF(K5="","",TEXT(K5,"mmm-yyyy")) -> Jul-2025 | R5: =IF(K5="","",DATE(YEAR(K5),MONTH(K5),1)) -> 45839
A6: TCK-000005 | B6: 2025-07-02T11:02:24Z | C6: 1936 | D6: Email | E6: Low | F6: Feature request | G6: 431 | H6: 3785 | I6: closed | J6: 4 | K6: =IF(B6="","",DATEVALUE(LEFT(B6,10))) -> 45840 | L6: =IF(H6="","",H6/60) -> 63.083333 | M6: =IF(G6="","",G6/60) -> 7.1833333 | N6: =IF(L6="","Open",IF(L6<=IF(E6="Urgent",8,IF(E6="High",24,IF(E6="Normal",48,72))),"Within SLA","Breached")) -> Within SLA | O6: =IF(J6="","No Rating",IF(J6>=4,"Satisfied",IF(J6=3,"Neutral","Dissatisfied"))) -> Satisfied | P6: =IF(I6="Closed","Resolved",IF(I6="Resolved","Resolved","Unresolved")) -> Resolved | Q6: =IF(K6="","",TEXT(K6,"mmm-yyyy")) -> Jul-2025 | R6: =IF(K6="","",DATE(YEAR(K6),MONTH(K6),1)) -> 45839
A7: TCK-000006 | C7: 1471 | D7: Social | E7: Low | F7: Feature request | G7: 302 | H7: 1808 | I7: closed | J7: 1 | K7: =IF(B7="","",DATEVALUE(LEFT(B7,10))) | L7: =IF(H7="","",H7/60) -> 30.133333 | M7: =IF(G7="","",G7/60) -> 5.0333333 | N7: =IF(L7="","Open",IF(L7<=IF(E7="Urgent",8,IF(E7="High",24,IF(E7="Normal",48,72))),"Within SLA","Breached")) -> Within SLA | O7: =IF(J7="","No Rating",IF(J7>=4,"Satisfied",IF(J7=3,"Neutral","Dissatisfied"))) -> Dissatisfied | P7: =IF(I7="Closed","Resolved",IF(I7="Resolved","Resolved","Unresolved")) -> Resolved | Q7: =IF(K7="","",TEXT(K7,"mmm-yyyy")) | R7: =IF(K7="","",DATE(YEAR(K7),MONTH(K7),1))
A8: TCK-000007 | B8: 2025-07-03T04:33:36Z | C8: 1949 | D8: Web form | E8: Low | F8: Performance | G8: 206 | H8: 2717 | I8: closed | J8: 1 | K8: =IF(B8="","",DATEVALUE(LEFT(B8,10))) -> 45841 | L8: =IF(H8="","",H8/60) -> 45.283333 | M8: =IF(G8="","",G8/60) -> 3.4333333 | N8: =IF(L8="","Open",IF(L8<=IF(E8="Urgent",8,IF(E8="High",24,IF(E8="Normal",48,72))),"Within SLA","Breached")) -> Within SLA | O8: =IF(J8="","No Rating",IF(J8>=4,"Satisfied",IF(J8=3,"Neutral","Dissatisfied"))) -> Dissatisfied | P8: =IF(I8="Closed","Resolved",IF(I8="Resolved","Resolved","Unresolved")) -> Resolved | Q8: =IF(K8="","",TEXT(K8,"mmm-yyyy")) -> Jul-2025 | R8: =IF(K8="","",DATE(YEAR(K8),MONTH(K8),1)) -> 45839
A9: TCK-000008 | B9: 2025-07-03T13:19:12Z | C9: 1968 | D9: Chat | E9: Normal | F9: Billing | G9: 85 | H9: 771 | I9: closed | K9: =IF(B9="","",DATEVALUE(LEFT(B9,10))) -> 45841 | L9: =IF(H9="","",H9/60) -> 12.85 | M9: =IF(G9="","",G9/60) -> 1.4166667 | N9: =IF(L9="","Open",IF(L9<=IF(E9="Urgent",8,IF(E9="High",24,IF(E9="Normal",48,72))),"Within SLA","Breached")) -> Within SLA | O9: =IF(J9="","No Rating",IF(J9>=4,"Satisfied",IF(J9=3,"Neutral","Dissatisfied"))) -> No Rating | P9: =IF(I9="Closed","Resolved",IF(I9="Resolved","Resolved","Unresolved")) -> Resolved | Q9: =IF(K9="","",TEXT(K9,"mmm-yyyy")) -> Jul-2025 | R9: =IF(K9="","",DATE(YEAR(K9),MONTH(K9),1)) -> 45839
A10: TCK-000009 | B10: 2025-07-03T22:04:48Z | C10: 1750 | D10: Chat | E10: Normal | F10: Integration | G10: 32 | I10: pending | K10: =IF(B10="","",DATEVALUE(LEFT(B10,10))) -> 45841 | L10: =IF(H10="","",H10/60) | M10: =IF(G10="","",G10/60) -> 0.53333333 | N10: =IF(L10="","Open",IF(L10<=IF(E10="Urgent",8,IF(E10="High",24,IF(E10="Normal",48,72))),"Within SLA","Breached")) -> Open | O10: =IF(J10="","No Rating",IF(J10>=4,"Satisfied",IF(J10=3,"Neutral","Dissatisfied"))) -> No Rating | P10: =IF(I10="Closed","Resolved",IF(I10="Resolved","Resolved","Unresolved")) -> Unresolved | Q10: =IF(K10="","",TEXT(K10,"mmm-yyyy")) -> Jul-2025 | R10: =IF(K10="","",DATE(YEAR(K10),MONTH(K10),1)) -> 45839
A11: TCK-000010 | B11: 2025-07-04T06:50:24Z | C11: 1591 | D11: Phone | E11: Normal | F11: Integration | G11: 63 | H11: 1975 | I11: closed | J11: 2 | K11: =IF(B11="","",DATEVALUE(LEFT(B11,10))) -> 45842 | L11: =IF(H11="","",H11/60) -> 32.916667 | M11: =IF(G11="","",G11/60) -> 1.05 | N11: =IF(L11="","Open",IF(L11<=IF(E11="Urgent",8,IF(E11="High",24,IF(E11="Normal",48,72))),"Within SLA","Breached")) -> Within SLA | O11: =IF(J11="","No Rating",IF(J11>=4,"Satisfied",IF(J11=3,"Neutral","Dissatisfied"))) -> Dissatisfied | P11: =IF(I11="Closed","Resolved",IF(I11="Resolved","Resolved","Unresolved")) -> Resolved | Q11: =IF(K11="","",TEXT(K11,"mmm-yyyy")) -> Jul-2025 | R11: =IF(K11="","",DATE(YEAR(K11),MONTH(K11),1)) -> 45839
A12: TCK-000011 | B12: 2025-07-04T15:36:00Z | C12: 1908 | D12: Chat | E12: High | F12: Data import | G12: 21 | H12: 174 | I12: resolved | J12: 1 | K12: =IF(B12="","",DATEVALUE(LEFT(B12,10))) -> 45842 | L12: =IF(H12="","",H12/60) -> 2.9 | M12: =IF(G12="","",G12/60) -> 0.35 | N12: =IF(L12="","Open",IF(L12<=IF(E12="Urgent",8,IF(E12="High",24,IF(E12="Normal",48,72))),"Within SLA","Breached")) -> Within SLA | O12: =IF(J12="","No Rating",IF(J12>=4,"Satisfied",IF(J12=3,"Neutral","Dissatisfied"))) -> Dissatisfied | P12: =IF(I12="Closed","Resolved",IF(I12="Resolved","Resolved","Unresolved")) -> Resolved | Q12: =IF(K12="","",TEXT(K12,"mmm-yyyy")) -> Jul-2025 | R12: =IF(K12="","",DATE(YEAR(K12),MONTH(K12),1)) -> 45839
A13: TCK-000012 | B13: 2025-07-05T00:21:36Z | C13: 1982 | D13: Social | E13: Low | F13: Performance | G13: 343 | H13: 6881 | I13: closed | K13: =IF(B13="","",DATEVALUE(LEFT(B13,10))) -> 45843 | L13: =IF(H13="","",H13/60) -> 114.68333 | M13: =IF(G13="","",G13/60) -> 5.7166667 | N13: =IF(L13="","Open",IF(L13<=IF(E13="Urgent",8,IF(E13="High",24,IF(E13="Normal",48,72))),"Within SLA","Breached")) -> Breached | O13: =IF(J13="","No Rating",IF(J13>=4,"Satisfied",IF(J13=3,"Neutral","Dissatisfied"))) -> No Rating | P13: =IF(I13="Closed","Resolved",IF(I13="Resolved","Resolved","Unresolved")) -> Resolved | Q13: =IF(K13="","",TEXT(K13,"mmm-yyyy")) -> Jul-2025 | R13: =IF(K13="","",DATE(YEAR(K13),MONTH(K13),1)) -> 45839
A14: TCK-000013 | B14: 2025-07-05T09:07:12Z | C14: 1099 | D14: Web form | E14: Low | F14: Bug report | G14: 442 | H14: 6637 | I14: closed | J14: 1 | K14: =IF(B14="","",DATEVALUE(LEFT(B14,10))) -> 45843 | L14: =IF(H14="","",H14/60) -> 110.61667 | M14: =IF(G14="","",G14/60) -> 7.3666667 | N14: =IF(L14="","Open",IF(L14<=IF(E14="Urgent",8,IF(E14="High",24,IF(E14="Normal",48,72))),"Within SLA","Breached")) -> Breached | O14: =IF(J14="","No Rating",IF(J14>=4,"Satisfied",IF(J14=3,"Neutral","Dissatisfied"))) -> Dissatisfied | P14: =IF(I14="Closed","Resolved",IF(I14="Resolved","Resolved","Unresolved")) -> Resolved | Q14: =IF(K14="","",TEXT(K14,"mmm-yyyy")) -> Jul-2025 | R14: =IF(K14="","",DATE(YEAR(K14),MONTH(K14),1)) -> 45839
A15: TCK-000014 | B15: 2025-07-05T17:52:48Z | C15: 1055 | D15: Web form | E15: Urgent | F15: Feature request | G15: 10 | H15: 406 | I15: closed | K15: =IF(B15="","",DATEVALUE(LEFT(B15,10))) -> 45843 | L15: =IF(H15="","",H15/60) -> 6.7666667 | M15: =IF(G15="","",G15/60) -> 0.16666667 | N15: =IF(L15="","Open",IF(L15<=IF(E15="Urgent",8,IF(E15="High",24,IF(E15="Normal",48,72))),"Within SLA","Breached")) -> Within SLA | O15: =IF(J15="","No Rating",IF(J15>=4,"Satisfied",IF(J15=3,"Neutral","Dissatisfied"))) -> No Rating | P15: =IF(I15="Closed","Resolved",IF(I15="Resolved","Resolved","Unresolved")) -> Resolved | Q15: =IF(K15="","",TEXT(K15,"mmm-yyyy")) -> Jul-2025 | R15: =IF(K15="","",DATE(YEAR(K15),MONTH(K15),1)) -> 45839
A16: TCK-000015 | B16: 2025-07-06T02:38:24Z | C16: 1214 | D16: Phone | E16: Low | F16: Export | G16: 122 | H16: 2695 | I16: resolved | J16: 3 | K16: =IF(B16="","",DATEVALUE(LEFT(B16,10))) -> 45844 | L16: =IF(H16="","",H16/60) -> 44.916667 | M16: =IF(G16="","",G16/60) -> 2.0333333 | N16: =IF(L16="","Open",IF(L16<=IF(E16="Urgent",8,IF(E16="High",24,IF(E16="Normal",48,72))),"Within SLA","Breached")) -> Within SLA | O16: =IF(J16="","No Rating",IF(J16>=4,"Satisfied",IF(J16=3,"Neutral","Dissatisfied"))) -> Neutral | P16: =IF(I16="Closed","Resolved",IF(I16="Resolved","Resolved","Unresolved")) -> Resolved | Q16: =IF(K16="","",TEXT(K16,"mmm-yyyy")) -> Jul-2025 | R16: =IF(K16="","",DATE(YEAR(K16),MONTH(K16),1)) -> 45839
A17: TCK-000016 | B17: 2025-07-06T11:24:00Z | C17: 1730 | D17: Web form | E17: Urgent | F17: Integration | G17: 3 | H17: 173 | I17: closed | J17: 2 | K17: =IF(B17="","",DATEVALUE(LEFT(B17,10))) -> 45844 | L17: =IF(H17="","",H17/60) -> 2.8833333 | M17: =IF(G17="","",G17/60) -> 0.05 | N17: =IF(L17="","Open",IF(L17<=IF(E17="Urgent",8,IF(E17="High",24,IF(E17="Normal",48,72))),"Within SLA","Breached")) -> Within SLA | O17: =IF(J17="","No Rating",IF(J17>=4,"Satisfied",IF(J17=3,"Neutral","Dissatisfied"))) -> Dissatisfied | P17: =IF(I17="Closed","Resolved",IF(I17="Resolved","Resolved","Unresolved")) -> Resolved | Q17: =IF(K17="","",TEXT(K17,"mmm-yyyy")) -> Jul-2025 | R17: =IF(K17="","",DATE(YEAR(K17),MONTH(K17),1)) -> 45839
A18: TCK-000017 | B18: 2025-07-06T20:09:36Z | C18: 1469 | D18: Phone | E18: Low | F18: Account | G18: 337 | H18: 6240 | I18: closed | K18: =IF(B18="","",DATEVALUE(LEFT(B18,10))) -> 45844 | L18: =IF(H18="","",H18/60) -> 104 | M18: =IF(G18="","",G18/60) -> 5.6166667 | N18: =IF(L18="","Open",IF(L18<=IF(E18="Urgent",8,IF(E18="High",24,IF(E18="Normal",48,72))),"Within SLA","Breached")) -> Breached | O18: =IF(J18="","No Rating",IF(J18>=4,"Satisfied",IF(J18=3,"Neutral","Dissatisfied"))) -> No Rating | P18: =IF(I18="Closed","Resolved",IF(I18="Resolved","Resolved","Unresolved")) -> Resolved | Q18: =IF(K18="","",TEXT(K18,"mmm-yyyy")) -> Jul-2025 | R18: =IF(K18="","",DATE(YEAR(K18),MONTH(K18),1)) -> 45839
A19: TCK-000018 | B19: 2025-07-07T04:55:12Z | C19: 1802 | D19: Email | E19: Normal | F19: Export | G19: 157 | I19: pending | K19: =IF(B19="","",DATEVALUE(LEFT(B19,10))) -> 45845 | L19: =IF(H19="","",H19/60) | M19: =IF(G19="","",G19/60) -> 2.6166667 | N19: =IF(L19="","Open",IF(L19<=IF(E19="Urgent",8,IF(E19="High",24,IF(E19="Normal",48,72))),"Within SLA","Breached")) -> Open | O19: =IF(J19="","No Rating",IF(J19>=4,"Satisfied",IF(J19=3,"Neutral","Dissatisfied"))) -> No Rating | P19: =IF(I19="Closed","Resolved",IF(I19="Resolved","Resolved","Unresolved")) -> Unresolved | Q19: =IF(K19="","",TEXT(K19,"mmm-yyyy")) -> Jul-2025 | R19: =IF(K19="","",DATE(YEAR(K19),MONTH(K19),1)) -> 45839
A20: TCK-000019 | B20: 2025-07-07T13:40:48Z | C20: 1538 | D20: Social | E20: Normal | F20: Account | G20: 166 | H20: 1810 | I20: resolved | K20: =IF(B20="","",DATEVALUE(LEFT(B20,10))) -> 45845 | L20: =IF(H20="","",H20/60) -> 30.166667 | M20: =IF(G20="","",G20/60) -> 2.7666667 | N20: =IF(L20="","Open",IF(L20<=IF(E20="Urgent",8,IF(E20="High",24,IF(E20="Normal",48,72))),"Within SLA","Breached")) -> Within SLA | O20: =IF(J20="","No Rating",IF(J20>=4,"Satisfied",IF(J20=3,"Neutral","Dissatisfied"))) -> No Rating | P20: =IF(I20="Closed","Resolved",IF(I20="Resolved","Resolved","Unresolved")) -> Resolved | Q20: =IF(K20="","",TEXT(K20,"mmm-yyyy")) -> Jul-2025 | R20: =IF(K20="","",DATE(YEAR(K20),MONTH(K20),1)) -> 45839
A21: TCK-000020 | B21: 2025-07-07T22:26:24Z | C21: 1295 | D21: Web form | E21: Urgent | F21: Login | G21: 3 | H21: 123 | I21: resolved | J21: 4 | K21: =IF(B21="","",DATEVALUE(LEFT(B21,10))) -> 45845 | L21: =IF(H21="","",H21/60) -> 2.05 | M21: =IF(G21="","",G21/60) -> 0.05 | N21: =IF(L21="","Open",IF(L21<=IF(E21="Urgent",8,IF(E21="High",24,IF(E21="Normal",48,72))),"Within SLA","Breached")) -> Within SLA | O21: =IF(J21="","No Rating",IF(J21>=4,"Satisfied",IF(J21=3,"Neutral","Dissatisfied"))) -> Satisfied | P21: =IF(I21="Closed","Resolved",IF(I21="Resolved","Resolved","Unresolved")) -> Resolved | Q21: =IF(K21="","",TEXT(K21,"mmm-yyyy")) -> Jul-2025 | R21: =IF(K21="","",DATE(YEAR(K21),MONTH(K21),1)) -> 45839
A22: TCK-000021 | B22: 2025-07-08T07:12:00Z | C22: 1646 | D22: Web form | E22: High | F22: Data import | G22: 15 | I22: open | K22: =IF(B22="","",DATEVALUE(LEFT(B22,10))) -> 45846 | L22: =IF(H22="","",H22/60) | M22: =IF(G22="","",G22/60) -> 0.25 | N22: =IF(L22="","Open",IF(L22<=IF(E22="Urgent",8,IF(E22="High",24,IF(E22="Normal",48,72))),"Within SLA","Breached")) -> Open | O22: =IF(J22="","No Rating",IF(J22>=4,"Satisfied",IF(J22=3,"Neutral","Dissatisfied"))) -> No Rating | P22: =IF(I22="Closed","Resolved",IF(I22="Resolved","Resolved","Unresolved")) -> Unresolved | Q22: =IF(K22="","",TEXT(K22,"mmm-yyyy")) -> Jul-2025 | R22: =IF(K22="","",DATE(YEAR(K22),MONTH(K22),1)) -> 45839
A23: TCK-000022 | B23: 2025-07-08T15:57:36Z | C23: 1880 | D23: Social | E23: Normal | F23: Login | G23: 46 | I23: open | K23: =IF(B23="","",DATEVALUE(LEFT(B23,10))) -> 45846 | L23: =IF(H23="","",H23/60) | M23: =IF(G23="","",G23/60) -> 0.76666667 | N23: =IF(L23="","Open",IF(L23<=IF(E23="Urgent",8,IF(E23="High",24,IF(E23="Normal",48,72))),"Within SLA","Breached")) -> Open | O23: =IF(J23="","No Rating",IF(J23>=4,"Satisfied",IF(J23=3,"Neutral","Dissatisfied"))) -> No Rating | P23: =IF(I23="Closed","Resolved",IF(I23="Resolved","Resolved","Unresolved")) -> Unresolved | Q23: =IF(K23="","",TEXT(K23,"mmm-yyyy")) -> Jul-2025 | R23: =IF(K23="","",DATE(YEAR(K23),MONTH(K23),1)) -> 45839
A24: TCK-000023 | B24: 2025-07-09T00:43:12Z | C24: 1808 | D24: Web form | E24: Low | F24: Performance | G24: 217 | H24: 6190 | I24: closed | K24: =IF(B24="","",DATEVALUE(LEFT(B24,10))) -> 45847 | L24: =IF(H24="","",H24/60) -> 103.16667 | M24: =IF(G24="","",G24/60) -> 3.6166667 | N24: =IF(L24="","Open",IF(L24<=IF(E24="Urgent",8,IF(E24="High",24,IF(E24="Normal",48,72))),"Within SLA","Breached")) -> Breached | O24: =IF(J24="","No Rating",IF(J24>=4,"Satisfied",IF(J24=3,"Neutral","Dissatisfied"))) -> No Rating | P24: =IF(I24="Closed","Resolved",IF(I24="Resolved","Resolved","Unresolved")) -> Resolved | Q24: =IF(K24="","",TEXT(K24,"mmm-yyyy")) -> Jul-2025 | R24: =IF(K24="","",DATE(YEAR(K24),MONTH(K24),1)) -> 45839
A25: TCK-000024 | B25: 2025-07-09T09:28:48Z | C25: 1887 | D25: Social | E25: Low | F25: Integration | G25: 263 | H25: 7047 | I25: closed | K25: =IF(B25="","",DATEVALUE(LEFT(B25,10))) -> 45847 | L25: =IF(H25="","",H25/60) -> 117.45 | M25: =IF(G25="","",G25/60) -> 4.3833333 | N25: =IF(L25="","Open",IF(L25<=IF(E25="Urgent",8,IF(E25="High",24,IF(E25="Normal",48,72))),"Within SLA","Breached")) -> Breached | O25: =IF(J25="","No Rating",IF(J25>=4,"Satisfied",IF(J25=3,"Neutral","Dissatisfied"))) -> No Rating | P25: =IF(I25="Closed","Resolved",IF(I25="Resolved","Resolved","Unresolved")) -> Resolved | Q25: =IF(K25="","",TEXT(K25,"mmm-yyyy")) -> Jul-2025 | R25: =IF(K25="","",DATE(YEAR(K25),MONTH(K25),1)) -> 45839
A26: TCK-000025 | B26: 2025-07-09T18:14:24Z | C26: 1909 | D26: Phone | E26: Low | F26: Performance | G26: 446 | I26: open | K26: =IF(B26="","",DATEVALUE(LEFT(B26,10))) -> 45847 | L26: =IF(H26="","",H26/60) | M26: =IF(G26="","",G26/60) -> 7.4333333 | N26: =IF(L26="","Open",IF(L26<=IF(E26="Urgent",8,IF(E26="High",24,IF(E26="Normal",48,72))),"Within SLA","Breached")) -> Open | O26: =IF(J26="","No Rating",IF(J26>=4,"Satisfied",IF(J26=3,"Neutral","Dissatisfied"))) -> No Rating | P26: =IF(I26="Closed","Resolved",IF(I26="Resolved","Resolved","Unresolved")) -> Unresolved | Q26: =IF(K26="","",TEXT(K26,"mmm-yyyy")) -> Jul-2025 | R26: =IF(K26="","",DATE(YEAR(K26),MONTH(K26),1)) -> 45839
A27: TCK-000026 | B27: 2025-07-10T03:00:00Z | C27: 1950 | D27: Chat | E27: Low | F27: Account | G27: 165 | I27: open | K27: =IF(B27="","",DATEVALUE(LEFT(B27,10))) -> 45848 | L27: =IF(H27="","",H27/60) | M27: =IF(G27="","",G27/60) -> 2.75 | N27: =IF(L27="","Open",IF(L27<=IF(E27="Urgent",8,IF(E27="High",24,IF(E27="Normal",48,72))),"Within SLA","Breached")) -> Open | O27: =IF(J27="","No Rating",IF(J27>=4,"Satisfied",IF(J27=3,"Neutral","Dissatisfied"))) -> No Rating | P27: =IF(I27="Closed","Resolved",IF(I27="Resolved","Resolved","Unresolved")) -> Unresolved | Q27: =IF(K27="","",TEXT(K27,"mmm-yyyy")) -> Jul-2025 | R27: =IF(K27="","",DATE(YEAR(K27),MONTH(K27),1)) -> 45839
A28: TCK-000027 | B28: 2025-07-10T11:45:36Z | C28: 1028 | D28: Phone | E28: Normal | F28: Export | G28: 123 | H28: 792 | I28: resolved | J28: 2 | K28: =IF(B28="","",DATEVALUE(LEFT(B28,10))) -> 45848 | L28: =IF(H28="","",H28/60) -> 13.2 | M28: =IF(G28="","",G28/60) -> 2.05 | N28: =IF(L28="","Open",IF(L28<=IF(E28="Urgent",8,IF(E28="High",24,IF(E28="Normal",48,72))),"Within SLA","Breached")) -> Within SLA | O28: =IF(J28="","No Rating",IF(J28>=4,"Satisfied",IF(J28=3,"Neutral","Dissatisfied"))) -> Dissatisfied | P28: =IF(I28="Closed","Resolved",IF(I28="Resolved","Resolved","Unresolved")) -> Resolved | Q28: =IF(K28="","",TEXT(K28,"mmm-yyyy")) -> Jul-2025 | R28: =IF(K28="","",DATE(YEAR(K28),MONTH(K28),1)) -> 45839
A29: TCK-000028 | B29: 2025-07-10T20:31:12Z | C29: 1035 | D29: Web form | E29: High | F29: Feature request | G29: 24 | H29: 235 | I29: closed | J29: 4 | K29: =IF(B29="","",DATEVALUE(LEFT(B29,10))) -> 45848 | L29: =IF(H29="","",H29/60) -> 3.9166667 | M29: =IF(G29="","",G29/60) -> 0.4 | N29: =IF(L29="","Open",IF(L29<=IF(E29="Urgent",8,IF(E29="High",24,IF(E29="Normal",48,72))),"Within SLA","Breached")) -> Within SLA | O29: =IF(J29="","No Rating",IF(J29>=4,"Satisfied",IF(J29=3,"Neutral","Dissatisfied"))) -> Satisfied | P29: =IF(I29="Closed","Resolved",IF(I29="Resolved","Resolved","Unresolved")) -> Resolved | Q29: =IF(K29="","",TEXT(K29,"mmm-yyyy")) -> Jul-2025 | R29: =IF(K29="","",DATE(YEAR(K29),MONTH(K29),1)) -> 45839
A30: TCK-000029 | B30: 2025-07-11T05:16:48Z | C30: 1426 | D30: Chat | E30: Low | F30: Feature request | G30: 405 | H30: 4942 | I30: closed | J30: 3 | K30: =IF(B30="","",DATEVALUE(LEFT(B30,10))) -> 45849 | L30: =IF(H30="","",H30/60) -> 82.366667 | M30: =IF(G30="","",G30/60) -> 6.75 | N30: =IF(L30="","Open",IF(L30<=IF(E30="Urgent",8,IF(E30="High",24,IF(E30="Normal",48,72))),"Within SLA","Breached")) -> Breached | O30: =IF(J30="","No Rating",IF(J30>=4,"Satisfied",IF(J30=3,"Neutral","Dissatisfied"))) -> Neutral | P30: =IF(I30="Closed","Resolved",IF(I30="Resolved","Resolved","Unresolved")) -> Resolved | Q30: =IF(K30="","",TEXT(K30,"mmm-yyyy")) -> Jul-2025 | R30: =IF(K30="","",DATE(YEAR(K30),MONTH(K30),1)) -> 45839
A31: TCK-000030 | B31: 2025-07-11T14:02:24Z | C31: 1908 | D31: Phone | E31: Low | F31: Account | G31: 432 | H31: 2314 | I31: closed | J31: 3 | K31: =IF(B31="","",DATEVALUE(LEFT(B31,10))) -> 45849 | L31: =IF(H31="","",H31/60) -> 38.566667 | M31: =IF(G31="","",G31/60) -> 7.2 | N31: =IF(L31="","Open",IF(L31<=IF(E31="Urgent",8,IF(E31="High",24,IF(E31="Normal",48,72))),"Within SLA","Breached")) -> Within SLA | O31: =IF(J31="","No Rating",IF(J31>=4,"Satisfied",IF(J31=3,"Neutral","Dissatisfied"))) -> Neutral | P31: =IF(I31="Closed","Resolved",IF(I31="Resolved","Resolved","Unresolved")) -> Resolved | Q31: =IF(K31="","",TEXT(K31,"mmm-yyyy")) -> Jul-2025 | R31: =IF(K31="","",DATE(YEAR(K31),MONTH(K31),1)) -> 45839
A32: TCK-000031 | B32: 2025-07-11T22:48:00Z | C32: 1540 | D32: Web form | E32: Normal | F32: Billing | G32: 90 | I32: open | K32: =IF(B32="","",DATEVALUE(LEFT(B32,10))) -> 45849 | L32: =IF(H32="","",H32/60) | M32: =IF(G32="","",G32/60) -> 1.5 | N32: =IF(L32="","Open",IF(L32<=IF(E32="Urgent",8,IF(E32="High",24,IF(E32="Normal",48,72))),"Within SLA","Breached")) -> Open | O32: =IF(J32="","No Rating",IF(J32>=4,"Satisfied",IF(J32=3,"Neutral","Dissatisfied"))) -> No Rating | P32: =IF(I32="Closed","Resolved",IF(I32="Resolved","Resolved","Unresolved")) -> Unresolved | Q32: =IF(K32="","",TEXT(K32,"mmm-yyyy")) -> Jul-2025 | R32: =IF(K32="","",DATE(YEAR(K32),MONTH(K32),1)) -> 45839
A33: TCK-000032 | B33: 2025-07-12T07:33:36Z | C33: 1059 | D33: Web form | E33: Urgent | F33: Bug report | G33: 2 | H33: 221 | I33: closed | J33: 4 | K33: =IF(B33="","",DATEVALUE(LEFT(B33,10))) -> 45850 | L33: =IF(H33="","",H33/60) -> 3.6833333 | M33: =IF(G33="","",G33/60) -> 0.033333333 | N33: =IF(L33="","Open",IF(L33<=IF(E33="Urgent",8,IF(E33="High",24,IF(E33="Normal",48,72))),"Within SLA","Breached")) -> Within SLA | O33: =IF(J33="","No Rating",IF(J33>=4,"Satisfied",IF(J33=3,"Neutral","Dissatisfied"))) -> Satisfied | P33: =IF(I33="Closed","Resolved",IF(I33="Resolved","Resolved","Unresolved")) -> Resolved | Q33: =IF(K33="","",TEXT(K33,"mmm-yyyy")) -> Jul-2025 | R33: =IF(K33="","",DATE(YEAR(K33),MONTH(K33),1)) -> 45839
A34: TCK-000033 | B34: 2025-07-12T16:19:12Z | C34: 1205 | D34: Email | E34: Urgent | F34: Data import | G34: 9 | H34: 422 | I34: resolved | J34: 3 | K34: =IF(B34="","",DATEVALUE(LEFT(B34,10))) -> 45850 | L34: =IF(H34="","",H34/60) -> 7.0333333 | M34: =IF(G34="","",G34/60) -> 0.15 | N34: =IF(L34="","Open",IF(L34<=IF(E34="Urgent",8,IF(E34="High",24,IF(E34="Normal",48,72))),"Within SLA","Breached")) -> Within SLA | O34: =IF(J34="","No Rating",IF(J34>=4,"Satisfied",IF(J34=3,"Neutral","Dissatisfied"))) -> Neutral | P34: =IF(I34="Closed","Resolved",IF(I34="Resolved","Resolved","Unresolved")) -> Resolved | Q34: =IF(K34="","",TEXT(K34,"mmm-yyyy")) -> Jul-2025 | R34: =IF(K34="","",DATE(YEAR(K34),MONTH(K34),1)) -> 45839
A35: TCK-000034 | B35: 2025-07-13T01:04:48Z | C35: 1441 | D35: Email | E35: Normal | F35: Billing | G35: 150 | H35: 1715 | I35: closed | J35: 1 | K35: =IF(B35="","",DATEVALUE(LEFT(B35,10))) -> 45851 | L35: =IF(H35="","",H35/60) -> 28.583333 | M35: =IF(G35="","",G35/60) -> 2.5 | N35: =IF(L35="","Open",IF(L35<=IF(E35="Urgent",8,IF(E35="High",24,IF(E35="Normal",48,72))),"Within SLA","Breached")) -> Within SLA | O35: =IF(J35="","No Rating",IF(J35>=4,"Satisfied",IF(J35=3,"Neutral","Dissatisfied"))) -> Dissatisfied | P35: =IF(I35="Closed","Resolved",IF(I35="Resolved","Resolved","Unresolved")) -> Resolved | Q35: =IF(K35="","",TEXT(K35,"mmm-yyyy")) -> Jul-2025 | R35: =IF(K35="","",DATE(YEAR(K35),MONTH(K35),1)) -> 45839
A36: TCK-000035 | B36: 2025-07-13T09:50:24Z | C36: 1403 | D36: Chat | E36: Normal | F36: Export | G36: 36 | H36: 3180 | I36: resolved | K36: =IF(B36="","",DATEVALUE(LEFT(B36,10))) -> 45851 | L36: =IF(H36="","",H36/60) -> 53 | M36: =IF(G36="","",G36/60) -> 0.6 | N36: =IF(L36="","Open",IF(L36<=IF(E36="Urgent",8,IF(E36="High",24,IF(E36="Normal",48,72))),"Within SLA","Breached")) -> Breached | O36: =IF(J36="","No Rating",IF(J36>=4,"Satisfied",IF(J36=3,"Neutral","Dissatisfied"))) -> No Rating | P36: =IF(I36="Closed","Resolved",IF(I36="Resolved","Resolved","Unresolved")) -> Resolved | Q36: =IF(K36="","",TEXT(K36,"mmm-yyyy")) -> Jul-2025 | R36: =IF(K36="","",DATE(YEAR(K36),MONTH(K36),1)) -> 45839
A37: TCK-000036 | B37: 2025-07-13T18:36:00Z | C37: 1702 | D37: Web form | E37: Low | F37: Integration | G37: 233 | H37: 2898 | I37: resolved | K37: =IF(B37="","",DATEVALUE(LEFT(B37,10))) -> 45851 | L37: =IF(H37="","",H37/60) -> 48.3 | M37: =IF(G37="","",G37/60) -> 3.8833333 | N37: =IF(L37="","Open",IF(L37<=IF(E37="Urgent",8,IF(E37="High",24,IF(E37="Normal",48,72))),"Within SLA","Breached")) -> Within SLA | O37: =IF(J37="","No Rating",IF(J37>=4,"Satisfied",IF(J37=3,"Neutral","Dissatisfied"))) -> No Rating | P37: =IF(I37="Closed","Resolved",IF(I37="Resolved","Resolved","Unresolved")) -> Resolved | Q37: =IF(K37="","",TEXT(K37,"mmm-yyyy")) -> Jul-2025 | R37: =IF(K37="","",DATE(YEAR(K37),MONTH(K37),1)) -> 45839
A38: TCK-000037 | B38: 2025-07-14T03:21:36Z | C38: 1041 | D38: Phone | E38: Urgent | F38: Integration | G38: 7 | H38: 427 | I38: closed | J38: 4 | K38: =IF(B38="","",DATEVALUE(LEFT(B38,10))) -> 45852 | L38: =IF(H38="","",H38/60) -> 7.1166667 | M38: =IF(G38="","",G38/60) -> 0.11666667 | N38: =IF(L38="","Open",IF(L38<=IF(E38="Urgent",8,IF(E38="High",24,IF(E38="Normal",48,72))),"Within SLA","Breached")) -> Within SLA | O38: =IF(J38="","No Rating",IF(J38>=4,"Satisfied",IF(J38=3,"Neutral","Dissatisfied"))) -> Satisfied | P38: =IF(I38="Closed","Resolved",IF(I38="Resolved","Resolved","Unresolved")) -> Resolved | Q38: =IF(K38="","",TEXT(K38,"mmm-yyyy")) -> Jul-2025 | R38: =IF(K38="","",DATE(YEAR(K38),MONTH(K38),1)) -> 45839
A39: TCK-000038 | B39: 2025-07-14T12:07:12Z | C39: 1169 | D39: Web form | E39: Low | F39: Bug report | G39: 335 | H39: 5407 | I39: closed | K39: =IF(B39="","",DATEVALUE(LEFT(B39,10))) -> 45852 | L39: =IF(H39="","",H39/60) -> 90.116667 | M39: =IF(G39="","",G39/60) -> 5.5833333 | N39: =IF(L39="","Open",IF(L39<=IF(E39="Urgent",8,IF(E39="High",24,IF(E39="Normal",48,72))),"Within SLA","Breached")) -> Breached | O39: =IF(J39="","No Rating",IF(J39>=4,"Satisfied",IF(J39=3,"Neutral","Dissatisfied"))) -> No Rating | P39: =IF(I39="Closed","Resolved",IF(I39="Resolved","Resolved","Unresolved")) -> Resolved | Q39: =IF(K39="","",TEXT(K39,"mmm-yyyy")) -> Jul-2025 | R39: =IF(K39="","",DATE(YEAR(K39),MONTH(K39),1)) -> 45839
A40: TCK-000039 | B40: 2025-07-14T20:52:48Z | C40: 1116 | D40: Web form | E40: Normal | F40: Integration | G40: 103 | I40: open | K40: =IF(B40="","",DATEVALUE(LEFT(B40,10))) -> 45852 | L40: =IF(H40="","",H40/60) | M40: =IF(G40="","",G40/60) -> 1.7166667 | N40: =IF(L40="","Open",IF(L40<=IF(E40="Urgent",8,IF(E40="High",24,IF(E40="Normal",48,72))),"Within SLA","Breached")) -> Open | O40: =IF(J40="","No Rating",IF(J40>=4,"Satisfied",IF(J40=3,"Neutral","Dissatisfied"))) -> No Rating | P40: =IF(I40="Closed","Resolved",IF(I40="Resolved","Resolved","Unresolved")) -> Unresolved | Q40: =IF(K40="","",TEXT(K40,"mmm-yyyy")) -> Jul-2025 | R40: =IF(K40="","",DATE(YEAR(K40),MONTH(K40),1)) -> 45839
...

Sheet Analysis
A1: Metric | B1: Value | D1: status | E1: Count of ticket_id | H1: Count of ticket_id | I1: SLA_Status | N1: Month_Date | O1: Count of ticket_id
A2: Total Tickets | B2: =COUNTA('Clean-Data'!A2:A1001) -> 1000 | D2: closed | E2: 616 | H2: priority | I2: Breached | J2: Open | K2: Within SLA | L2: Grand Total | O2: 1
A3: Resolved Ticket | B3: =COUNTIF('Clean-Data'!P2:P1001,"Resolved") -> 835 | D3: open | E3: 93 | H3: High | J3: 26 | K3: 145 | L3: 171 | N3: 45839 | O3: 84
A4: Unresolved Tickets | B4: =COUNTIF('Clean-Data'!P2:P1001,"Unresolved") -> 165 | D4: pending | E4: 72 | H4: Low | I4: 96 | J4: 39 | K4: 79 | L4: 214 | N4: 45870 | O4: 85
A5: Resolution Rate | B5: =B3/B2 -> 0.835 | D5: resolved | E5: 219 | H5: Normal | I5: 83 | J5: 67 | K5: 255 | L5: 405 | N5: 45901 | O5: 83
A6: Average Response Time (Hours) | B6: =AVERAGE('Clean-Data'!M2:M1001) -> 1.8076167 | D6: Grand Total | E6: 1000 | H6: Urgent | J6: 33 | K6: 177 | L6: 210 | N6: 45931 | O6: 84
A7: Average Resolution Time (Hours) | B7: =AVERAGE('Clean-Data'!L2:L1001) -> 33.61479 | H7: Grand Total | I7: 179 | J7: 165 | K7: 656 | L7: 1000 | N7: 45962 | O7: 83
A8: SLA Compliance % | B8: =COUNTIF('Clean-Data'!N2:N1001,"Within SLA")/B3 -> 0.78562874 | N8: 45992 | O8: 85
A9: Average Satisfaction | B9: =AVERAGE('Clean-Data'!J2:J1001) -> 2.9696395 | N9: 46023 | O9: 85
A10: Unresolved Rate | B10: =B4/B2 -> 0.165 | D10: priority | E10: Count of ticket_id | N10: 46054 | O10: 76
D11: High | E11: 171 | N11: 46082 | O11: 85
A12: Tickets by Channel | D12: Low | E12: 214 | H12: category | I12: Average of resolution_hours | N12: 46113 | O12: 82
A13: Channel | B13: Ticket Count | D13: Normal | E13: 405 | H13: Account | I13: 34.145155 | N13: 46143 | O13: 85
D14: Urgent | E14: 210 | H14: Billing | I14: 34.113441 | N14: 46174 | O14: 82
D15: Grand Total | E15: 1000 | H15: Bug report | I15: 34.926603 | N15: Grand Total | O15: 1000
H16: Data import | I16: 31.922222
H17: Export | I17: 34.811798
D18: channel | E18: Count of ticket_id | H18: Feature request | I18: 36.205303
D19: Chat | E19: 202 | H19: Integration | I19: 33.558648
D20: Email | E20: 199 | H20: Login | I20: 28.245556
D21: Phone | E21: 178 | H21: Performance | I21: 34.587791
D22: Social | E22: 221 | H22: Grand Total | I22: 33.61479
D23: Web form | E23: 200
D24: Grand Total | E24: 1000
D26: category | E26: Count of ticket_id
D27: Account | E27: 107
D28: Billing | E28: 105
D29: Bug report | E29: 130
D30: Data import | E30: 117
D31: Export | E31: 103
D32: Feature request | E32: 101
D33: Integration | E33: 120
D34: Login | E34: 106
D35: Performance | E35: 111
D36: Grand Total | E36: 1000

Sheet Dashboard
A1: Customer Support Operations Dashboard
A3: Total Tickets | C3: Resolution Rate | E3: SLA Compliance | G3: Avg Resolution Time | I3: Avg Satisfaction | L3: Key Insights
A4: =Analysis!B2 -> 1000 | C4: =Analysis!B5 -> 0.835 | E4: =Analysis!B8 -> 0.78562874 | G4: =Analysis!B7 -> 33.61479 | I4: =Analysis!B9 -> 2.9696395 | L4: • 83.5% of tickets were resolved, while 16.5% remained unresolved.
L5: • SLA compliance was 78.6%, with 179 tickets breaching the defined SLA thresholds.
L6: • Normal-priority tickets had the highest volume, with 405 tickets.
L7: • Low-priority tickets had the highest number of SLA breaches, with 96 breaches.
L8: • Chat was the highest-volume support channel, indicating significant customer reliance on real-time support.
L9: • Average resolution time was 33.6 hours, highlighting an opportunity to improve turnaround time and operational efficiency.
